Workbook

Sheet #150
A1: Flange Rating Verification as per ASME VIII Div.1 UG-44(b) | AB1: Updated on : | AD1: 44467
M2: Design Pressure (kPa) | O2: 710
A3: Rating 150 | M3: Design Pressure+ Static Head (kPa) | O3: =O2+AD3 -> 710 | R3: Liquid Specific Gravity (SG) | U3: 1 | W3: Max. Liquid Height (m) | Z3: 0 | AB3: Static Head (kPa) | AD3: =U3*Z3*9.80665 -> 0
A4: SIZE | B4: ME (KN-m) | C4: ME (KN-m) Resolved | D4: FE (KN) | E4: G (m) | F4: Gasket ID (mm) | G4: Gasket OD (mm) | H4: G (mm) | I4: PR (KN/m2) | J4: PD (KN/m2) | K4: FM | M4: LHS | O4: RHS | Q4: Warning | U4: UG-44 (b)
A5: 2 | B5: 0.145 | C5: =SQRT(B5*B5+B5*B5) -> 0.20506097 | D5: 0.55 | E5: =H5/1000 -> 0.0779 | F5: 69.9 | G5: 85.9 | H5: =((G5-F5)/2)+F5 -> 77.9 | I5: 1380 | J5: =O$3 -> 710 | K5: 1.2 | M5: =((16*C5)+(4*D5*E5)) -> 3.4523555 | O5: =(3.14*E5*E5*E5)*((I5-J5)+(K5*I5)) -> 3.4526434 | Q5: =IF(M5>O5,"ERROR","OK") -> OK
A6: 3 | B6: 1.1 | C6: =SQRT(B6*B6+B6*B6) -> 1.5556349 | D6: 1.8 | E6: =H6/1000 -> 0.11115 | F6: 101.6 | G6: 120.7 | H6: =((G6-F6)/2)+F6 -> 111.15 | I6: =I$5 -> 1380 | J6: =O$3 -> 710 | K6: 1.2 | M6: =((16*C6)+(4*D6*E6)) -> 25.690439 | O6: =(3.14*E6*E6*E6)*((I6-J6)+(K6*I6)) -> 10.029234 | Q6: =IF(M6>O6,"ERROR","OK") -> ERROR
A7: 4 | B7: 0.816 | C7: =SQRT(B7*B7+B7*B7) -> 1.1539983 | D7: 1.3 | E7: =H7/1000 -> 0.1382 | F7: 127 | G7: 149.4 | H7: =((G7-F7)/2)+F7 -> 138.2 | I7: =I$5 -> 1380 | J7: =O$3 -> 710 | K7: 1.2 | M7: =((16*C7)+(4*D7*E7)) -> 19.182612 | O7: =(3.14*E7*E7*E7)*((I7-J7)+(K7*I7)) -> 19.278067 | Q7: =IF(M7>O7,"ERROR","OK") -> OK
A8: 6 | B8: 3.7 | C8: =SQRT(B8*B8+B8*B8) -> 5.2325902 | D8: 3.8 | E8: =H8/1000 -> 0.1961 | F8: 182.6 | G8: 209.6 | H8: =((G8-F8)/2)+F8 -> 196.1 | I8: =I$5 -> 1380 | J8: =O$3 -> 710 | K8: 1.2 | M8: =((16*C8)+(4*D8*E8)) -> 86.702163 | O8: =(3.14*E8*E8*E8)*((I8-J8)+(K8*I8)) -> 55.077236 | Q8: =IF(M8>O8,"ERROR","OK") -> ERROR
A9: 8 | B9: 6.1 | C9: =SQRT(B9*B9+B9*B9) -> 8.6267027 | D9: 5.4 | E9: =H9/1000 -> 0.24855 | F9: 233.4 | G9: 263.7 | H9: =((G9-F9)/2)+F9 -> 248.55 | I9: =I$5 -> 1380 | J9: =O$3 -> 710 | K9: 1.2 | M9: =((16*C9)+(4*D9*E9)) -> 143.39592 | O9: =(3.14*E9*E9*E9)*((I9-J9)+(K9*I9)) -> 112.14519 | Q9: =IF(M9>O9,"ERROR","OK") -> ERROR | AB9: 16ME + 4FEG (LHS) | AE9: 3.14 G3[(PR-PD)+FMPR] (RHS)
A10: 10 | B10: 9 | C10: =SQRT(B10*B10+B10*B10) -> 12.727922 | D10: 7.1 | E10: =H10/1000 -> 0.3024 | F10: 287.3 | G10: 317.5 | H10: =((G10-F10)/2)+F10 -> 302.4 | I10: =I$5 -> 1380 | J10: =O$3 -> 710 | K10: 1.2 | M10: =((16*C10)+(4*D10*E10)) -> 212.23491 | O10: =(3.14*E10*E10*E10)*((I10-J10)+(K10*I10)) -> 201.969 | Q10: =IF(M10>O10,"ERROR","OK") -> ERROR
A11: 12 | B11: 12.3 | C11: =SQRT(B11*B11+B11*B11) -> 17.394827 | D11: 8.9 | E11: =H11/1000 -> 0.3573 | F11: 339.9 | G11: 374.7 | H11: =((G11-F11)/2)+F11 -> 357.3 | I11: =I$5 -> 1380 | J11: =O$3 -> 710 | K11: 1.2 | M11: =((16*C11)+(4*D11*E11)) -> 291.03711 | O11: =(3.14*E11*E11*E11)*((I11-J11)+(K11*I11)) -> 333.14892 | Q11: =IF(M11>O11,"ERROR","OK") -> OK | AB11: ME | AC11: External Moment
A12: 14 | B12: 16.1 | C12: =SQRT(B12*B12+B12*B12) -> 22.768838 | D12: 10.7 | E12: =H12/1000 -> 0.389 | F12: 371.6 | G12: 406.4 | H12: =((G12-F12)/2)+F12 -> 389 | I12: =I$5 -> 1380 | J12: =O$3 -> 710 | K12: 1.2 | M12: =((16*C12)+(4*D12*E12)) -> 380.95061 | O12: =(3.14*E12*E12*E12)*((I12-J12)+(K12*I12)) -> 429.92051 | Q12: =IF(M12>O12,"ERROR","OK") -> OK | AB12: FE | AC12: External Tensil axial Force
A13: 16 | B13: 20.3 | C13: =SQRT(B13*B13+B13*B13) -> 28.708535 | D13: 12.5 | E13: =H13/1000 -> 0.443 | F13: 422.4 | G13: 463.6 | H13: =((G13-F13)/2)+F13 -> 443 | I13: =I$5 -> 1380 | J13: =O$3 -> 710 | K13: 1.2 | M13: =((16*C13)+(4*D13*E13)) -> 481.48657 | O13: =(3.14*E13*E13*E13)*((I13-J13)+(K13*I13)) -> 634.9661 | Q13: =IF(M13>O13,"ERROR","OK") -> OK | AB13: G | AC13: Gasket reaction diameter
A14: 18 | B14: 24.9 | C14: =SQRT(B14*B14+B14*B14) -> 35.213918 | D14: 14.5 | E14: =H14/1000 -> 0.5009 | F14: 474.7 | G14: 527.1 | H14: =((G14-F14)/2)+F14 -> 500.9 | I14: =I$5 -> 1380 | J14: =O$3 -> 710 | K14: 1.2 | M14: =((16*C14)+(4*D14*E14)) -> 592.47488 | O14: =(3.14*E14*E14*E14)*((I14-J14)+(K14*I14)) -> 917.89384 | Q14: =IF(M14>O14,"ERROR","OK") -> OK | AB14: PR | AC14: Flange Pressure Rating at design temp
A15: 20 | B15: 30.1 | C15: =SQRT(B15*B15+B15*B15) -> 42.567828 | D15: 16.4 | E15: =H15/1000 -> 0.5517 | F15: 525.5 | G15: 577.9 | H15: =((G15-F15)/2)+F15 -> 551.7 | I15: =I$5 -> 1380 | J15: =O$3 -> 710 | K15: 1.2 | M15: =((16*C15)+(4*D15*E15)) -> 717.27677 | O15: =(3.14*E15*E15*E15)*((I15-J15)+(K15*I15)) -> 1226.4457 | Q15: =IF(M15>O15,"ERROR","OK") -> OK | AB15: PD | AC15: Vessel MAWP corrected or design pressure
A16: 36 | C16: 680.188 | D16: 25.927 | E16: 0.9886 | H16: 988.6 | I16: 3712.053 | J16: 420.361 | K16: 0.1 | M16: =((16*C16)+(4*D16*E16)) -> 10985.534 | O16: =(3.14*E16*E16*E16)*((I16-J16)+(K16*I16)) -> 11112.613 | Q16: =IF(M16>O16,"ERROR","OK") -> OK | AB16: FM | AC16: Moment Factor (table UG-44-1)
A18: 26 | B18: 45.3 | C18: =SQRT(B18*B18+B18*B18) -> 64.063874 | D18: 22.1 | E18: =H18/1000 -> 0.689 | F18: 673.1 | G18: 704.9 | H18: =((G18-F18)/2)+F18 -> 689 | I18: =I$5 -> 1380 | J18: =O$3 -> 710 | K18: 0.6 | M18: =((16*C18)+(4*D18*E18)) -> 1085.9296 | O18: =(3.14*E18*E18*E18)*((I18-J18)+(K18*I18)) -> 1538.5058 | Q18: =IF(M18>O18,"ERROR","OK") -> OK
A19: 28 | B19: 48.8 | C19: =SQRT(B19*B19+B19*B19) -> 69.013622 | D19: 23.8 | E19: =H19/1000 -> 0.7398 | F19: 723.9 | G19: 755.7 | H19: =((G19-F19)/2)+F19 -> 739.8 | I19: =I$5 -> 1380 | J19: =O$3 -> 710 | K19: 0.6 | M19: =((16*C19)+(4*D19*E19)) -> 1174.6469 | O19: =(3.14*E19*E19*E19)*((I19-J19)+(K19*I19)) -> 1904.5152 | Q19: =IF(M19>O19,"ERROR","OK") -> OK
A20: 30 | B20: 52.3 | C20: =SQRT(B20*B20+B20*B20) -> 73.963369 | D20: 25.5 | E20: =H20/1000 -> 0.7906 | F20: 774.7 | G20: 806.5 | H20: =((G20-F20)/2)+F20 -> 790.6 | I20: =I$5 -> 1380 | J20: =O$3 -> 710 | K20: 0.6 | M20: =((16*C20)+(4*D20*E20)) -> 1264.0551 | O20: =(3.14*E20*E20*E20)*((I20-J20)+(K20*I20)) -> 2324.4055 | Q20: =IF(M20>O20,"ERROR","OK") -> OK
A21: 32 | B21: 55.7 | C21: =SQRT(B21*B21+B21*B21) -> 78.771695 | D21: 27.2 | E21: =H21/1000 -> 0.84305 | F21: 825.5 | G21: 860.6 | H21: =((G21-F21)/2)+F21 -> 843.05 | I21: =I$5 -> 1380 | J21: =O$3 -> 710 | K21: 0.6 | M21: =((16*C21)+(4*D21*E21)) -> 1352.071 | O21: =(3.14*E21*E21*E21)*((I21-J21)+(K21*I21)) -> 2818.3924 | Q21: =IF(M21>O21,"ERROR","OK") -> OK
A22: 34 | B22: 59.2 | C22: =SQRT(B22*B22+B22*B22) -> 83.721443 | D22: 28.9 | E22: =H22/1000 -> 0.89385 | F22: 876.3 | G22: 911.4 | H22: =((G22-F22)/2)+F22 -> 893.85 | I22: =I$5 -> 1380 | J22: =O$3 -> 710 | K22: 0.6 | M22: =((16*C22)+(4*D22*E22)) -> 1442.8721 | O22: =(3.14*E22*E22*E22)*((I22-J22)+(K22*I22)) -> 3359.1964 | Q22: =IF(M22>O22,"ERROR","OK") -> OK
A23: 36 | B23: 62.7 | C23: =SQRT(B23*B23+B23*B23) -> 88.67119 | D23: 30.6 | E23: =H23/1000 -> 0.9478 | F23: 927.1 | G23: 968.5 | H23: =((G23-F23)/2)+F23 -> 947.8 | I23: =I$5 -> 1380 | J23: =O$3 -> 710 | K23: 0.6 | M23: =((16*C23)+(4*D23*E23)) -> 1534.7498 | O23: =(3.14*E23*E23*E23)*((I23-J23)+(K23*I23)) -> 4004.8991 | Q23: =IF(M23>O23,"ERROR","OK") -> OK
A24: 38 | B24: 66.2 | C24: =SQRT(B24*B24+B24*B24) -> 93.620938 | D24: 32.3 | E24: =H24/1000 -> 0.9986 | F24: 977.9 | G24: 1019.3 | H24: =((G24-F24)/2)+F24 -> 998.6 | I24: =I$5 -> 1380 | J24: =O$3 -> 710 | K24: 0.6 | M24: =((16*C24)+(4*D24*E24)) -> 1626.9541 | O24: =(3.14*E24*E24*E24)*((I24-J24)+(K24*I24)) -> 4683.992 | Q24: =IF(M24>O24,"ERROR","OK") -> OK
A25: 40 | B25: 69.7 | C25: =SQRT(B25*B25+B25*B25) -> 98.570685 | D25: 34 | E25: =H25/1000 -> 1.0494 | F25: 1028.7 | G25: 1070.1 | H25: =((G25-F25)/2)+F25 -> 1049.4 | I25: =I$5 -> 1380 | J25: =O$3 -> 710 | K25: 0.6 | M25: =((16*C25)+(4*D25*E25)) -> 1719.8494 | O25: =(3.14*E25*E25*E25)*((I25-J25)+(K25*I25)) -> 5435.8147 | Q25: =IF(M25>O25,"ERROR","OK") -> OK
A26: 48 | B26: 83.6 | C26: =SQRT(B26*B26+B26*B26) -> 118.22825 | D26: 40.8 | E26: =H26/1000 -> 1.2558 | F26: 1231.9 | G26: 1279.7 | H26: =((G26-F26)/2)+F26 -> 1255.8 | I26: =I$5 -> 1380 | J26: =O$3 -> 710 | K26: 0.6 | M26: =((16*C26)+(4*D26*E26)) -> 2096.5986 | O26: =(3.14*E26*E26*E26)*((I26-J26)+(K26*I26)) -> 9315.4298 | Q26: =IF(M26>O26,"ERROR","OK") -> OK
A30: * | B30: Input data shall be in Yellow cells only
B31: Other Cells are automaticlly filled
J35: =K16*I16+I16-M16/(3.14*E16*E16*E16) -> 462.24854

Sheet PVlite report

Sheet Sheet2
A15: JOBNAME | B15: ELEMENTID | C15: TO_NODE | D15: SIZE | E15: Rating | F15: ME(KN-m) Resolved | G15: FE(KN) | H15: G(m) | I15: PR(KN/m2) | J15: PD(KN/m2) | K15: FM | L15: LHS | M15: RHS
D16: 10 | E16: 150 | F16: ='#150'!C10 -> 12.727922 | G16: ='#150'!D10 -> 7.1 | H16: ='#150'!E10 -> 0.3024 | I16: ='#150'!I10 -> 1380 | J16: ='#150'!J10 -> 710 | K16: 1.2

Sheet Sheet1
A1: SIZE | B1: Rating | C1: ME (KN-m) | D1: ME (KN-m) Resolved | E1: FE (KN) | F1: G (m) | G1: Gasket ID (mm) | H1: Gasket OD (mm) | I1: G (mm) | J1: PR (KN/m2) | K1: PD (KN/m2) | L1: FM
A2: 2 | B2: 150 | C2: 0.38 | D2: 0.53740115 | E2: 1 | F2: 0.0779 | G2: 69.9 | H2: 85.9 | I2: 77.9 | J2: 1770 | K2: 700 | L2: 1.2
A3: 3 | B3: 150 | C3: 1.1 | D3: 1.5556349 | E3: 1.8 | F3: 0.11115 | G3: 101.6 | H3: 120.7 | I3: 111.15 | J3: 1770 | K3: 700 | L3: 1.2
A4: 4 | B4: 150 | C4: 1.7 | D4: 2.4041631 | E4: 2.3 | F4: 0.1382 | G4: 127 | H4: 149.4 | I4: 138.2 | J4: 1770 | K4: 700 | L4: 1.2
A5: 6 | B5: 150 | C5: 3.7 | D5: 5.2325902 | E5: 3.8 | F5: 0.1961 | G5: 182.6 | H5: 209.6 | I5: 196.1 | J5: 1770 | K5: 700 | L5: 1.2
A6: 8 | B6: 150 | C6: 6.1 | D6: 8.6267027 | E6: 5.4 | F6: 0.24855 | G6: 233.4 | H6: 263.7 | I6: 248.55 | J6: 1770 | K6: 700 | L6: 1.2
A7: 10 | B7: 150 | C7: 9 | D7: 12.727922 | E7: 7.1 | F7: 0.3024 | G7: 287.3 | H7: 317.5 | I7: 302.4 | J7: 1770 | K7: 700 | L7: 1.2
A8: 12 | B8: 150 | C8: 12.3 | D8: 17.394827 | E8: 8.9 | F8: 0.3573 | G8: 339.9 | H8: 374.7 | I8: 357.3 | J8: 1770 | K8: 700 | L8: 1.2
A9: 14 | B9: 150 | C9: 16.1 | D9: 22.768838 | E9: 10.7 | F9: 0.389 | G9: 371.6 | H9: 406.4 | I9: 389 | J9: 1770 | K9: 700 | L9: 1.2
A10: 16 | B10: 150 | C10: 20.3 | D10: 28.708535 | E10: 12.5 | F10: 0.443 | G10: 422.4 | H10: 463.6 | I10: 443 | J10: 1770 | K10: 700 | L10: 1.2
A11: 18 | B11: 150 | C11: 24.9 | D11: 35.213918 | E11: 14.5 | F11: 0.5009 | G11: 474.7 | H11: 527.1 | I11: 500.9 | J11: 1770 | K11: 700 | L11: 1.2
A12: 20 | B12: 150 | C12: 30.1 | D12: 42.567828 | E12: 16.4 | F12: 0.5517 | G12: 525.5 | H12: 577.9 | I12: 551.7 | J12: 1770 | K12: 700 | L12: 1.2
A13: 24 | B13: 150 | C13: 41.8 | D13: 59.114127 | E13: 20.4 | F13: 0.65725 | G13: 628.7 | H13: 685.8 | I13: 657.25 | J13: 1770 | K13: 700 | L13: 1.2
... A35: 24 | B35: 300 | C35: 54 | D35: 76.367532 | E35: 26.9 | F35: 0.65725 | G35: 628.7 | H35: 685.8 | I35: 657.25 | J35: 4660 | K35: 700 | L35: 0.5
B36: 300
A37: 26 | B37: 300 | C37: 58.5 | D37: 82.731493 | E37: 29.1 | F37: 0.7112 | G37: 685.8 | H37: 736.6 | I37: 711.2 | J37: 4660 | K37: 700 | L37: 0.1
A38: 28 | B38: 300 | C38: 63 | D38: 89.095454 | E38: 31.4 | F38: 0.762 | G38: 736.6 | H38: 787.4 | I38: 762 | J38: 4660 | K38: 700 | L38: 0.1
A39: 30 | B39: 300 | C39: 67.5 | D39: 95.459415 | E39: 33.6 | F39: 0.8192 | G39: 793.8 | H39: 844.6 | I39: 819.2 | J39: 4660 | K39: 700 | L39: 0.1
A40: 32 | B40: 300 | C40: 72 | D40: 101.82338 | E40: 35.9 | F40: 0.8763 | G40: 850.9 | H40: 901.7 | I40: 876.3 | J40: 4660 | K40: 700 | L40: 0.1
A41: 34 | B41: 300 | C41: 76.5 | D41: 108.18734 | E41: 38.1 | F41: 0.9271 | G41: 901.7 | H41: 952.5 | I41: 927.1 | J41: 4660 | K41: 700 | L41: 0.1
A42: 36 | B42: 300 | C42: 81 | D42: 114.5513 | E42: 40.4 | F42: 0.9812 | G42: 955.8 | H42: 1006.6 | I42: 981.2 | J42: 4660 | K42: 700 | L42: 0.1
A43: 38 | B43: 300 | C43: 85.5 | D43: 120.91526 | E43: 42.6 | F43: 0.99695 | G43: 977.9 | H43: 1016 | I43: 996.95 | J43: 4660 | K43: 700 | L43: 0.1
A44: 40 | B44: 300 | C44: 90 | D44: 127.27922 | E44: 44.8 | F44: 1.04625 | G44: 1022.4 | H44: 1070.1 | I44: 1046.25 | J44: 4660 | K44: 700 | L44: 0.1
A45: 48 | B45: 300 | C45: 108 | D45: 152.73506 | E45: 53.8 | F45: 1.2606 | G45: 1235.2 | H45: 1286 | I45: 1260.6 | J45: 4660 | K45: 700 | L45: 0.1
A46: 2 | B46: 600 | C46: 0.4 | D46: 0.56568542 | E46: 1.9 | F46: 0.0779 | G46: 69.9 | H46: 85.9 | I46: 77.9 | J46: 9320 | K46: 9323.2908 | L46: 0.5
A47: 3 | B47: 600 | C47: 1.3 | D47: 1.8384776 | E47: 3.3 | F47: 0.11115 | G47: 101.6 | H47: 120.7 | I47: 111.15 | J47: 9320 | K47: 9323.2908 | L47: 0.5
A48: 4 | B48: 600 | C48: 2.1 | D48: 2.9698485 | E48: 4.4 | F48: 0.13505 | G48: 120.7 | H48: 149.4 | I48: 135.05 | J48: 9320 | K48: 9323.2908 | L48: 0.5
... A57: 24 | B57: 600 | C57: 92.6 | D57: 130.95618 | E57: 37.7 | F57: 0.65725 | G57: 628.7 | H57: 685.8 | I57: 657.25 | J57: 9320 | K57: 9323.2908 | L57: 0.5
B58: 600
A59: 26 | B59: 600 | C59: 100.3 | D59: 141.84562 | E59: 40.8 | F59: 0.7112 | G59: 685.8 | H59: 736.6 | I59: 711.2 | J59: 9320 | K59: 9323.2908 | L59: 0.1
A60: 28 | B60: 600 | C60: 108 | D60: 152.73506 | E60: 44 | F60: 0.762 | G60: 736.6 | H60: 787.4 | I60: 762 | J60: 9320 | K60: 9323.2908 | L60: 0.1
A61: 30 | B61: 600 | C61: 115.8 | D61: 163.76593 | E61: 47.1 | F61: 0.8192 | G61: 793.8 | H61: 844.6 | I61: 819.2 | J61: 9320 | K61: 9323.2908 | L61: 0.1
A62: 32 | B62: 600 | C62: 123.5 | D62: 174.65537 | E62: 50.3 | F62: 0.8763 | G62: 850.9 | H62: 901.7 | I62: 876.3 | J62: 9320 | K62: 9323.2908 | L62: 0.1
A63: 34 | B63: 600 | C63: 131.2 | D63: 185.54482 | E63: 53.4 | F63: 0.9271 | G63: 901.7 | H63: 952.5 | I63: 927.1 | J63: 9320 | K63: 9323.2908 | L63: 0.1
A64: 36 | B64: 600 | C64: 138.9 | D64: 196.43426 | E64: 56.6 | F64: 0.9812 | G64: 955.8 | H64: 1006.6 | I64: 981.2 | J64: 9320 | K64: 9323.2908 | L64: 0.1
A65: 38 | B65: 600 | C65: 146.6 | D65: 207.32371 | E65: 59.7 | F65: 1.00965 | G65: 977.9 | H65: 1041.4 | I65: 1009.65 | J65: 9320 | K65: 9323.2908 | L65: 0.1
A66: 40 | B66: 600 | C66: 154.3 | D66: 218.21315 | E66: 62.8 | F66: 1.0605 | G66: 1022.4 | H66: 1098.6 | I66: 1060.5 | J66: 9320 | K66: 9323.2908 | L66: 0.1
A67: 48 | B67: 600 | C67: 185.2 | D67: 261.91235 | E67: 75.4 | F67: 1.278 | G67: 1235.2 | H67: 1320.8 | I67: 1278 | J67: 9320 | K67: 9323.2908 | L67: 0.1
A68: 2 | B68: 900 | C68: 0.4 | D68: 0.56568542 | E68: 2.4 | F68: 0.0723 | G68: 58.7 | H68: 85.9 | I68: 72.3 | J68: 13980 | K68: 9323.2908 | L68: 0.5
A69: 3 | B69: 900 | C69: 1.5 | D69: 2.1213203 | E69: 4.3 | F69: 0.108 | G69: 95.3 | H69: 120.7 | I69: 108 | J69: 13980 | K69: 9323.2908 | L69: 0.5
...

Sheet #300
N2: Design Pressure (kPa) | P2: 685
A3: Rating 300 | N3: Design Pressure+ Static Head (kPa) | P3: =P2+AE3 -> 685 | S3: Liquid Specific Gravity (SG) | V3: 1 | X3: Max. Liquid Height (m) | AA3: 0 | AC3: Static Head (kPa) | AE3: =V3*AA3*9.80665 -> 0
A4: SIZE | C4: ME (KN-m) | D4: ME (KN-m) Resolved | E4: FE (KN) | F4: G (m) | G4: Gasket ID (mm) | H4: Gasket OD (mm) | I4: G (mm) | J4: PR (KN/m2) | K4: PD (KN/m2) | L4: FM | N4: LHS | P4: RHS | R4: Warning | V4: UG-44 (b)
A5: 2 | C5: 0.4 | D5: =SQRT(C5*C5+C5*C5) -> 0.56568542 | E5: 1.3 | F5: =I5/1000 -> 0.0779 | G5: 69.9 | H5: 85.9 | I5: =((H5-G5)/2)+G5 -> 77.9 | J5: 4660 | K5: =P$3 -> 685 | L5: 0.5 | N5: =((16*D5)+(4*E5*F5)) -> 9.4560468 | P5: =(3.14*F5*F5*F5)*((J5-K5)+(L5*J5)) -> 9.3589497 | R5: =IF(N5>P5,"ERROR","OK") -> ERROR
A6: 3 | C6: 1.2 | D6: =SQRT(C6*C6+C6*C6) -> 1.6970563 | E6: 2.4 | F6: =I6/1000 -> 0.11115 | G6: 101.6 | H6: 120.7 | I6: =((H6-G6)/2)+G6 -> 111.15 | J6: =J$5 -> 4660 | K6: =P$3 -> 685 | L6: 0.5 | N6: =((16*D6)+(4*E6*F6)) -> 28.21994 | P6: =(3.14*F6*F6*F6)*((J6-K6)+(L6*J6)) -> 27.185864 | R6: =IF(N6>P6,"ERROR","OK") -> ERROR
A7: 4 | C7: 1.9 | D7: =SQRT(C7*C7+C7*C7) -> 2.6870058 | E7: 3.1 | F7: =I7/1000 -> 0.1382 | G7: 127 | H7: 149.4 | I7: =((H7-G7)/2)+G7 -> 138.2 | J7: =J$5 -> 4660 | K7: =P$3 -> 685 | L7: 0.5 | N7: =((16*D7)+(4*E7*F7)) -> 44.705772 | P7: =(3.14*F7*F7*F7)*((J7-K7)+(L7*J7)) -> 52.256325 | R7: =IF(N7>P7,"ERROR","OK") -> OK
A8: 6 | C8: 4.2 | D8: =SQRT(C8*C8+C8*C8) -> 5.939697 | E8: 5.1 | F8: =I8/1000 -> 0.1961 | G8: 182.6 | H8: 209.6 | I8: =((H8-G8)/2)+G8 -> 196.1 | J8: =J$5 -> 4660 | K8: =P$3 -> 685 | L8: 0.5 | N8: =((16*D8)+(4*E8*F8)) -> 99.035591 | P8: =(3.14*F8*F8*F8)*((J8-K8)+(L8*J8)) -> 149.29578 | R8: =IF(N8>P8,"ERROR","OK") -> OK
A9: 8 | C9: 7.1 | D9: =SQRT(C9*C9+C9*C9) -> 10.040916 | E9: 7.2 | F9: =I9/1000 -> 0.24855 | G9: 233.4 | H9: 263.7 | I9: =((H9-G9)/2)+G9 -> 248.55 | J9: =J$5 -> 4660 | K9: =P$3 -> 685 | L9: 0.5 | N9: =((16*D9)+(4*E9*F9)) -> 167.8129 | P9: =(3.14*F9*F9*F9)*((J9-K9)+(L9*J9)) -> 303.98772 | R9: =IF(N9>P9,"ERROR","OK") -> OK | AC9: 16ME + 4FEG (LHS) | AF9: 3.14 G3[(PR-PD)+FMPR] (RHS)
A10: 10 | C10: 10.8 | D10: =SQRT(C10*C10+C10*C10) -> 15.273506 | E10: 9.4 | F10: =I10/1000 -> 0.3024 | G10: 287.3 | H10: 317.5 | I10: =((H10-G10)/2)+G10 -> 302.4 | J10: =J$5 -> 4660 | K10: =P$3 -> 685 | L10: 0.5 | N10: =((16*D10)+(4*E10*F10)) -> 255.74634 | P10: =(3.14*F10*F10*F10)*((J10-K10)+(L10*J10)) -> 547.46971 | R10: =IF(N10>P10,"ERROR","OK") -> OK
A11: 12 | C11: 15.2 | D11: =SQRT(C11*C11+C11*C11) -> 21.496046 | E11: 11.7 | F11: =I11/1000 -> 0.3573 | G11: 339.9 | H11: 374.7 | I11: =((H11-G11)/2)+G11 -> 357.3 | J11: =J$5 -> 4660 | K11: =P$3 -> 685 | L11: 0.5 | N11: =((16*D11)+(4*E11*F11)) -> 360.65838 | P11: =(3.14*F11*F11*F11)*((J11-K11)+(L11*J11)) -> 903.05414 | R11: =IF(N11>P11,"ERROR","OK") -> OK | AC11: ME | AD11: External Moment
A12: 14 | C12: 20.5 | D12: =SQRT(C12*C12+C12*C12) -> 28.991378 | E12: 14.1 | F12: =I12/1000 -> 0.389 | G12: 371.6 | H12: 406.4 | I12: =((H12-G12)/2)+G12 -> 389 | J12: =J$5 -> 4660 | K12: =P$3 -> 685 | L12: 0.5 | N12: =((16*D12)+(4*E12*F12)) -> 485.80165 | P12: =(3.14*F12*F12*F12)*((J12-K12)+(L12*J12)) -> 1165.3692 | R12: =IF(N12>P12,"ERROR","OK") -> OK | AC12: FE | AD12: External Tensil axial Force
A13: 16 | C13: 26.6 | D13: =SQRT(C13*C13+C13*C13) -> 37.618081 | E13: 16.5 | F13: =I13/1000 -> 0.443 | G13: 422.4 | H13: 463.6 | I13: =((H13-G13)/2)+G13 -> 443 | J13: =J$5 -> 4660 | K13: =P$3 -> 685 | L13: 0.5 | N13: =((16*D13)+(4*E13*F13)) -> 631.12729 | P13: =(3.14*F13*F13*F13)*((J13-K13)+(L13*J13)) -> 1721.1785 | R13: =IF(N13>P13,"ERROR","OK") -> OK | AC13: G | AD13: Gasket reaction diameter
A14: 18 | C14: 33.7 | D14: =SQRT(C14*C14+C14*C14) -> 47.658997 | E14: 19 | F14: =I14/1000 -> 0.5009 | G14: 474.7 | H14: 527.1 | I14: =((H14-G14)/2)+G14 -> 500.9 | J14: =J$5 -> 4660 | K14: =P$3 -> 685 | L14: 0.5 | N14: =((16*D14)+(4*E14*F14)) -> 800.61235 | P14: =(3.14*F14*F14*F14)*((J14-K14)+(L14*J14)) -> 2488.1 | R14: =IF(N14>P14,"ERROR","OK") -> OK | AC14: PR | AD14: Flange Pressure Rating at design temp
A15: 20 | C15: 41.7 | D15: =SQRT(C15*C15+C15*C15) -> 58.972706 | E15: 21.6 | F15: =I15/1000 -> 0.5517 | G15: 525.5 | H15: 577.9 | I15: =((H15-G15)/2)+G15 -> 551.7 | J15: =J$5 -> 4660 | K15: =P$3 -> 685 | L15: 0.5 | N15: =((16*D15)+(4*E15*F15)) -> 991.23017 | P15: =(3.14*F15*F15*F15)*((J15-K15)+(L15*J15)) -> 3324.4797 | R15: =IF(N15>P15,"ERROR","OK") -> OK | AC15: PD | AD15: Vessel MAWP corrected or design pressure
A16: 24 | C16: 54 | D16: =SQRT(C16*C16+C16*C16) -> 76.367532 | E16: 26.9 | F16: =I16/1000 -> 0.65725 | G16: 628.7 | H16: 685.8 | I16: =((H16-G16)/2)+G16 -> 657.25 | J16: =J$5 -> 4660 | K16: =P$3 -> 685 | L16: 0.5 | N16: =((16*D16)+(4*E16*F16)) -> 1292.6006 | P16: =(3.14*F16*F16*F16)*((J16-K16)+(L16*J16)) -> 5620.9086 | R16: =IF(N16>P16,"ERROR","OK") -> OK | AC16: FM | AD16: Moment Factor (table UG-44-1)
A18: 26 | C18: 58.5 | D18: =SQRT(C18*C18+C18*C18) -> 82.731493 | E18: 29.1 | F18: =I18/1000 -> 0.7112 | G18: 685.8 | H18: 736.6 | I18: =((H18-G18)/2)+G18 -> 711.2 | J18: =J$5 -> 4660 | K18: =P$3 -> 685 | L18: 0.1 | N18: =((16*D18)+(4*E18*F18)) -> 1406.4876 | P18: =(3.14*F18*F18*F18)*((J18-K18)+(L18*J18)) -> 5016.325 | R18: =IF(N18>P18,"ERROR","OK") -> OK
A19: 28 | C19: 63 | D19: =SQRT(C19*C19+C19*C19) -> 89.095454 | E19: 31.4 | F19: =I19/1000 -> 0.762 | G19: 736.6 | H19: 787.4 | I19: =((H19-G19)/2)+G19 -> 762 | J19: =J$5 -> 4660 | K19: =P$3 -> 685 | L19: 0.1 | N19: =((16*D19)+(4*E19*F19)) -> 1521.2345 | P19: =(3.14*F19*F19*F19)*((J19-K19)+(L19*J19)) -> 6169.8604 | R19: =IF(N19>P19,"ERROR","OK") -> OK
A20: 30 | C20: 150 | D20: 150 | E20: 150 | F20: =I20/1000 -> 0.8192 | G20: 793.8 | H20: 844.6 | I20: =((H20-G20)/2)+G20 -> 819.2 | J20: =J$5 -> 4660 | K20: =P$3 -> 685 | L20: 0.1 | N20: =((16*D20)+(4*E20*F20)) -> 2891.52 | P20: =(3.14*F20*F20*F20)*((J20-K20)+(L20*J20)) -> 7666.2019 | R20: =IF(N20>P20,"ERROR","OK") -> OK
A21: 32 | C21: 72 | D21: =SQRT(C21*C21+C21*C21) -> 101.82338 | E21: 35.9 | F21: =I21/1000 -> 0.8763 | G21: 850.9 | H21: 901.7 | I21: =((H21-G21)/2)+G21 -> 876.3 | J21: =J$5 -> 4660 | K21: =P$3 -> 685 | L21: 0.1 | N21: =((16*D21)+(4*E21*F21)) -> 1755.0107 | P21: =(3.14*F21*F21*F21)*((J21-K21)+(L21*J21)) -> 9383.5864 | R21: =IF(N21>P21,"ERROR","OK") -> OK
A22: 34 | C22: 76.5 | D22: =SQRT(C22*C22+C22*C22) -> 108.18734 | E22: 38.1 | F22: =I22/1000 -> 0.9271 | G22: 901.7 | H22: 952.5 | I22: =((H22-G22)/2)+G22 -> 927.1 | J22: =J$5 -> 4660 | K22: =P$3 -> 685 | L22: 0.1 | N22: =((16*D22)+(4*E22*F22)) -> 1872.2874 | P22: =(3.14*F22*F22*F22)*((J22-K22)+(L22*J22)) -> 11111.947 | R22: =IF(N22>P22,"ERROR","OK") -> OK
A23: 36 | C23: 81 | D23: =SQRT(C23*C23+C23*C23) -> 114.5513 | E23: 40.4 | F23: =I23/1000 -> 0.9812 | G23: 955.8 | H23: 1006.6 | I23: =((H23-G23)/2)+G23 -> 981.2 | J23: =J$5 -> 4660 | K23: =P$3 -> 685 | L23: 0.1 | N23: =((16*D23)+(4*E23*F23)) -> 1991.3827 | P23: =(3.14*F23*F23*F23)*((J23-K23)+(L23*J23)) -> 13172.95 | R23: =IF(N23>P23,"ERROR","OK") -> OK
A24: 38 | C24: 85.5 | D24: =SQRT(C24*C24+C24*C24) -> 120.91526 | E24: 42.6 | F24: =I24/1000 -> 0.99695 | G24: 977.9 | H24: 1016 | I24: =((H24-G24)/2)+G24 -> 996.95 | J24: =J$5 -> 4660 | K24: =P$3 -> 685 | L24: 0.1 | N24: =((16*D24)+(4*E24*F24)) -> 2104.5244 | P24: =(3.14*F24*F24*F24)*((J24-K24)+(L24*J24)) -> 13817.534 | R24: =IF(N24>P24,"ERROR","OK") -> OK
A25: 40 | C25: 90 | D25: =SQRT(C25*C25+C25*C25) -> 127.27922 | E25: 44.8 | F25: =I25/1000 -> 1.04625 | G25: 1022.4 | H25: 1070.1 | I25: =((H25-G25)/2)+G25 -> 1046.25 | J25: =J$5 -> 4660 | K25: =P$3 -> 685 | L25: 0.1 | N25: =((16*D25)+(4*E25*F25)) -> 2223.9555 | P25: =(3.14*F25*F25*F25)*((J25-K25)+(L25*J25)) -> 15970.438 | R25: =IF(N25>P25,"ERROR","OK") -> OK
A26: 48 | C26: 108 | D26: =SQRT(C26*C26+C26*C26) -> 152.73506 | E26: 53.8 | F26: =I26/1000 -> 1.2606 | G26: 1235.2 | H26: 1286 | I26: =((H26-G26)/2)+G26 -> 1260.6 | J26: =J$5 -> 4660 | K26: =P$3 -> 685 | L26: 0.1 | N26: =((16*D26)+(4*E26*F26)) -> 2715.0422 | P26: =(3.14*F26*F26*F26)*((J26-K26)+(L26*J26)) -> 27934.592 | R26: =IF(N26>P26,"ERROR","OK") -> OK

Sheet #600
M2: Design Pressure (kPa) | O2: 9300
A3: Rating 600 | M3: Design Pressure+ Static Head (kPa) | O3: =O2+AD3 -> 9323.2908 | R3: Liquid Specific Gravity (SG) | U3: 1 | W3: Max. Liquid Height (m) | Z3: 2.375 | AB3: Static Head (kPa) | AD3: =U3*Z3*9.80665 -> 23.290794
A4: SIZE | B4: ME (KN-m) | C4: ME (KN-m) Resolved | D4: FE (KN) | E4: G (m) | F4: Gasket ID (mm) | G4: Gasket OD (mm) | H4: G (mm) | I4: PR (KN/m2) | J4: PD (KN/m2) | K4: FM | M4: LHS | O4: RHS | Q4: Warning | U4: UG-44 (b)
A5: 2 | B5: 0.4 | C5: =SQRT(B5*B5+B5*B5) -> 0.56568542 | D5: 1.9 | E5: =H5/1000 -> 0.0779 | F5: 69.9 | G5: 85.9 | H5: =((G5-F5)/2)+F5 -> 77.9 | I5: 9320 | J5: =O$3 -> 9323.2908 | K5: 0.5 | M5: =((16*C5)+(4*D5*E5)) -> 9.6430068 | O5: =(3.14*E5*E5*E5)*((I5-J5)+(K5*I5)) -> 6.9122771 | Q5: =IF(M5>O5,"ERROR","OK") -> ERROR
A6: 3 | B6: 1.3 | C6: =SQRT(B6*B6+B6*B6) -> 1.8384776 | D6: 3.3 | E6: =H6/1000 -> 0.11115 | F6: 101.6 | G6: 120.7 | H6: =((G6-F6)/2)+F6 -> 111.15 | I6: =I$5 -> 9320 | J6: =O$3 -> 9323.2908 | K6: 0.5 | M6: =((16*C6)+(4*D6*E6)) -> 30.882822 | O6: =(3.14*E6*E6*E6)*((I6-J6)+(K6*I6)) -> 20.078773 | Q6: =IF(M6>O6,"ERROR","OK") -> ERROR
A7: 4 | B7: 2.1 | C7: =SQRT(B7*B7+B7*B7) -> 2.9698485 | D7: 4.4 | E7: =H7/1000 -> 0.13505 | F7: 120.7 | G7: 149.4 | H7: =((G7-F7)/2)+F7 -> 135.05 | I7: =I$5 -> 9320 | J7: =O$3 -> 9323.2908 | K7: 0.5 | M7: =((16*C7)+(4*D7*E7)) -> 49.894456 | O7: =(3.14*E7*E7*E7)*((I7-J7)+(K7*I7)) -> 36.015756 | Q7: =IF(M7>O7,"ERROR","OK") -> ERROR
A8: 6 | B8: 4.9 | C8: =SQRT(B8*B8+B8*B8) -> 6.9296465 | D8: 7.1 | E8: =H8/1000 -> 0.1922 | F8: 174.8 | G8: 209.6 | H8: =((G8-F8)/2)+F8 -> 192.2 | I8: =I$5 -> 9320 | J8: =O$3 -> 9323.2908 | K8: 0.5 | M8: =((16*C8)+(4*D8*E8)) -> 116.33282 | O8: =(3.14*E8*E8*E8)*((I8-J8)+(K8*I8)) -> 103.81711 | Q8: =IF(M8>O8,"ERROR","OK") -> ERROR
A9: 8 | B9: 8.7 | C9: =SQRT(B9*B9+B9*B9) -> 12.303658 | D9: 10.1 | E9: =H9/1000 -> 0.24465 | F9: 225.6 | G9: 263.7 | H9: =((G9-F9)/2)+F9 -> 244.65 | I9: =I$5 -> 9320 | J9: =O$3 -> 9323.2908 | K9: 0.5 | M9: =((16*C9)+(4*D9*E9)) -> 206.74239 | O9: =(3.14*E9*E9*E9)*((I9-J9)+(K9*I9)) -> 214.11369 | Q9: =IF(M9>O9,"ERROR","OK") -> OK | AB9: 16ME + 4FEG (LHS) | AE9: 3.14 G3[(PR-PD)+FMPR] (RHS)
A10: 10 | B10: 13.8 | C10: =SQRT(B10*B10+B10*B10) -> 19.516147 | D10: 13.2 | E10: =H10/1000 -> 0.29605 | F10: 274.6 | G10: 317.5 | H10: =((G10-F10)/2)+F10 -> 296.05 | I10: =I$5 -> 9320 | J10: =O$3 -> 9323.2908 | K10: 0.5 | M10: =((16*C10)+(4*D10*E10)) -> 327.88979 | O10: =(3.14*E10*E10*E10)*((I10-J10)+(K10*I10)) -> 379.4058 | Q10: =IF(M10>O10,"ERROR","OK") -> OK
A11: 12 | B11: 20.1 | C11: =SQRT(B11*B11+B11*B11) -> 28.425693 | D11: 16.4 | E11: =H11/1000 -> 0.35095 | F11: 327.2 | G11: 374.7 | H11: =((G11-F11)/2)+F11 -> 350.95 | I11: =I$5 -> 9320 | J11: =O$3 -> 9323.2908 | K11: 0.5 | M11: =((16*C11)+(4*D11*E11)) -> 477.8334 | O11: =(3.14*E11*E11*E11)*((I11-J11)+(K11*I11)) -> 632.03992 | Q11: =IF(M11>O11,"ERROR","OK") -> OK | AB11: ME | AC11: External Moment
A12: 14 | B12: 27.9 | C12: =SQRT(B12*B12+B12*B12) -> 39.456558 | D12: 19.7 | E12: =H12/1000 -> 0.3842 | F12: 362 | G12: 406.4 | H12: =((G12-F12)/2)+F12 -> 384.2 | I12: =I$5 -> 9320 | J12: =O$3 -> 9323.2908 | K12: 0.5 | M12: =((16*C12)+(4*D12*E12)) -> 661.57989 | O12: =(3.14*E12*E12*E12)*((I12-J12)+(K12*I12)) -> 829.24116 | Q12: =IF(M12>O12,"ERROR","OK") -> OK | AB12: FE | AC12: External Tensil axial Force
A13: 16 | B13: 37.2 | C13: =SQRT(B13*B13+B13*B13) -> 52.608745 | D13: 23.2 | E13: =H13/1000 -> 0.4382 | F13: 412.8 | G13: 463.6 | H13: =((G13-F13)/2)+F13 -> 438.2 | I13: =I$5 -> 9320 | J13: =O$3 -> 9323.2908 | K13: 0.5 | M13: =((16*C13)+(4*D13*E13)) -> 882.40487 | O13: =(3.14*E13*E13*E13)*((I13-J13)+(K13*I13)) -> 1230.3421 | Q13: =IF(M13>O13,"ERROR","OK") -> OK | AB13: G | AC13: Gasket reaction diameter
A14: 18 | B14: 48.2 | C14: =SQRT(B14*B14+B14*B14) -> 68.165094 | D14: 26.7 | E14: =H14/1000 -> 0.4985 | F14: 469.9 | G14: 527.1 | H14: =((G14-F14)/2)+F14 -> 498.5 | I14: =I$5 -> 9320 | J14: =O$3 -> 9323.2908 | K14: 0.5 | M14: =((16*C14)+(4*D14*E14)) -> 1143.8813 | O14: =(3.14*E14*E14*E14)*((I14-J14)+(K14*I14)) -> 1811.3578 | Q14: =IF(M14>O14,"ERROR","OK") -> OK | AB14: PR | AC14: Flange Pressure Rating at design temp
A15: 20 | B15: 61.1 | C15: =SQRT(B15*B15+B15*B15) -> 86.408449 | D15: 30.3 | E15: =H15/1000 -> 0.5493 | F15: 520.7 | G15: 577.9 | H15: =((G15-F15)/2)+F15 -> 549.3 | I15: =I$5 -> 9320 | J15: =O$3 -> 9323.2908 | K15: 0.5 | M15: =((16*C15)+(4*D15*E15)) -> 1449.1103 | O15: =(3.14*E15*E15*E15)*((I15-J15)+(K15*I15)) -> 2423.4695 | Q15: =IF(M15>O15,"ERROR","OK") -> OK | AB15: PD | AC15: Vessel MAWP corrected or design pressure
A16: 24 | B16: 92.6 | C16: =SQRT(B16*B16+B16*B16) -> 130.95618 | D16: 37.7 | E16: =H16/1000 -> 0.65725 | F16: 628.7 | G16: 685.8 | H16: =((G16-F16)/2)+F16 -> 657.25 | I16: =I$5 -> 9320 | J16: =O$3 -> 9323.2908 | K16: 0.5 | M16: =((16*C16)+(4*D16*E16)) -> 2194.4121 | O16: =(3.14*E16*E16*E16)*((I16-J16)+(K16*I16)) -> 4151.4571 | Q16: =IF(M16>O16,"ERROR","OK") -> OK | AB16: FM | AC16: Moment Factor (table UG-44-1)
A18: 26 | B18: 100.3 | C18: =SQRT(B18*B18+B18*B18) -> 141.84562 | D18: 40.8 | E18: =H18/1000 -> 0.7112 | F18: 685.8 | G18: 736.6 | H18: =((G18-F18)/2)+F18 -> 711.2 | I18: =I$5 -> 9320 | J18: =O$3 -> 9323.2908 | K18: 0.1 | M18: =((16*C18)+(4*D18*E18)) -> 2385.5978 | O18: =(3.14*E18*E18*E18)*((I18-J18)+(K18*I18)) -> 1049.0221 | Q18: =IF(M18>O18,"ERROR","OK") -> ERROR
A19: 28 | B19: 108 | C19: =SQRT(B19*B19+B19*B19) -> 152.73506 | D19: 44 | E19: =H19/1000 -> 0.762 | F19: 736.6 | G19: 787.4 | H19: =((G19-F19)/2)+F19 -> 762 | I19: =I$5 -> 9320 | J19: =O$3 -> 9323.2908 | K19: 0.1 | M19: =((16*C19)+(4*D19*E19)) -> 2577.873 | O19: =(3.14*E19*E19*E19)*((I19-J19)+(K19*I19)) -> 1290.2513 | Q19: =IF(M19>O19,"ERROR","OK") -> ERROR
A20: 30 | B20: 115.8 | C20: =SQRT(B20*B20+B20*B20) -> 163.76593 | D20: 47.1 | E20: =H20/1000 -> 0.8192 | F20: 793.8 | G20: 844.6 | H20: =((G20-F20)/2)+F20 -> 819.2 | I20: =I$5 -> 9320 | J20: =O$3 -> 9323.2908 | K20: 0.1 | M20: =((16*C20)+(4*D20*E20)) -> 2774.5922 | O20: =(3.14*E20*E20*E20)*((I20-J20)+(K20*I20)) -> 1603.1687 | Q20: =IF(M20>O20,"ERROR","OK") -> ERROR
A21: 32 | B21: 123.5 | C21: =SQRT(B21*B21+B21*B21) -> 174.65537 | D21: 50.3 | E21: =H21/1000 -> 0.8763 | F21: 850.9 | G21: 901.7 | H21: =((G21-F21)/2)+F21 -> 876.3 | I21: =I$5 -> 9320 | J21: =O$3 -> 9323.2908 | K21: 0.1 | M21: =((16*C21)+(4*D21*E21)) -> 2970.7976 | O21: =(3.14*E21*E21*E21)*((I21-J21)+(K21*I21)) -> 1962.311 | Q21: =IF(M21>O21,"ERROR","OK") -> ERROR
A22: 34 | B22: 131.2 | C22: =SQRT(B22*B22+B22*B22) -> 185.54482 | D22: 53.4 | E22: =H22/1000 -> 0.9271 | F22: 901.7 | G22: 952.5 | H22: =((G22-F22)/2)+F22 -> 927.1 | I22: =I$5 -> 9320 | J22: =O$3 -> 9323.2908 | K22: 0.1 | M22: =((16*C22)+(4*D22*E22)) -> 3166.7457 | O22: =(3.14*E22*E22*E22)*((I22-J22)+(K22*I22)) -> 2323.7486 | Q22: =IF(M22>O22,"ERROR","OK") -> ERROR
A23: 36 | B23: 138.9 | C23: =SQRT(B23*B23+B23*B23) -> 196.43426 | D23: 56.6 | E23: =H23/1000 -> 0.9812 | F23: 955.8 | G23: 1006.6 | H23: =((G23-F23)/2)+F23 -> 981.2 | I23: =I$5 -> 9320 | J23: =O$3 -> 9323.2908 | K23: 0.1 | M23: =((16*C23)+(4*D23*E23)) -> 3365.0919 | O23: =(3.14*E23*E23*E23)*((I23-J23)+(K23*I23)) -> 2754.7489 | Q23: =IF(M23>O23,"ERROR","OK") -> ERROR
A24: 38 | B24: 146.6 | C24: =SQRT(B24*B24+B24*B24) -> 207.32371 | D24: 59.7 | E24: =H24/1000 -> 1.00965 | F24: 977.9 | G24: 1041.4 | H24: =((G24-F24)/2)+F24 -> 1009.65 | I24: =I$5 -> 9320 | J24: =O$3 -> 9323.2908 | K24: 0.1 | M24: =((16*C24)+(4*D24*E24)) -> 3558.2838 | O24: =(3.14*E24*E24*E24)*((I24-J24)+(K24*I24)) -> 3001.3867 | Q24: =IF(M24>O24,"ERROR","OK") -> ERROR
A25: 40 | B25: 154.3 | C25: =SQRT(B25*B25+B25*B25) -> 218.21315 | D25: 62.8 | E25: =H25/1000 -> 1.0605 | F25: 1022.4 | G25: 1098.6 | H25: =((G25-F25)/2)+F25 -> 1060.5 | I25: =I$5 -> 9320 | J25: =O$3 -> 9323.2908 | K25: 0.1 | M25: =((16*C25)+(4*D25*E25)) -> 3757.808 | O25: =(3.14*E25*E25*E25)*((I25-J25)+(K25*I25)) -> 3478.0948 | Q25: =IF(M25>O25,"ERROR","OK") -> ERROR
A26: 48 | B26: 185.2 | C26: =SQRT(B26*B26+B26*B26) -> 261.91235 | D26: 75.4 | E26: =H26/1000 -> 1.278 | F26: 1235.2 | G26: 1320.8 | H26: =((G26-F26)/2)+F26 -> 1278 | I26: =I$5 -> 9320 | J26: =O$3 -> 9323.2908 | K26: 0.1 | M26: =((16*C26)+(4*D26*E26)) -> 4576.0424 | O26: =(3.14*E26*E26*E26)*((I26-J26)+(K26*I26)) -> 6086.9812 | Q26: =IF(M26>O26,"ERROR","OK") -> OK

Sheet #900
M2: Design Pressure (kPa) | O2: 9300
A3: Rating 900 | M3: Design Pressure+ Static Head (kPa) | O3: =O2+AD3 -> 9323.2908 | R3: Liquid Specific Gravity (SG) | U3: 1 | W3: Max. Liquid Height (m) | Z3: 2.375 | AB3: Static Head (kPa) | AD3: =U3*Z3*9.80665 -> 23.290794
A4: SIZE | B4: ME (KN-m) | C4: ME (KN-m) Resolved | D4: FE (KN) | E4: G (m) | F4: Gasket ID (mm) | G4: Gasket OD (mm) | H4: G (mm) | I4: PR (KN/m2) | J4: PD (KN/m2) | K4: FM | M4: LHS | O4: RHS | Q4: Warning | U4: UG-44 (b)
A5: 2 | B5: 0.4 | C5: =SQRT(B5*B5+B5*B5) -> 0.56568542 | D5: 2.4 | E5: =H5/1000 -> 0.0723 | F5: 58.7 | G5: 85.9 | H5: =((G5-F5)/2)+F5 -> 72.3 | I5: 13980 | J5: =O$3 -> 9323.2908 | K5: 0.5 | M5: =((16*C5)+(4*D5*E5)) -> 9.7450468 | O5: =(3.14*E5*E5*E5)*((I5-J5)+(K5*I5)) -> 13.821264 | Q5: =IF(M5>O5,"ERROR","OK") -> OK
A6: 3 | B6: 1.5 | C6: =SQRT(B6*B6+B6*B6) -> 2.1213203 | D6: 4.3 | E6: =H6/1000 -> 0.108 | F6: 95.3 | G6: 120.7 | H6: =((G6-F6)/2)+F6 -> 108 | I6: =I$5 -> 13980 | J6: =O$3 -> 9323.2908 | K6: 0.5 | M6: =((16*C6)+(4*D6*E6)) -> 35.798725 | O6: =(3.14*E6*E6*E6)*((I6-J6)+(K6*I6)) -> 46.068508 | Q6: =IF(M6>O6,"ERROR","OK") -> OK
A7: 4 | B7: 2.4 | C7: =SQRT(B7*B7+B7*B7) -> 3.3941125 | D7: 5.6 | E7: =H7/1000 -> 0.13505 | F7: 120.7 | G7: 149.4 | H7: =((G7-F7)/2)+F7 -> 135.05 | I7: =I$5 -> 13980 | J7: =O$3 -> 9323.2908 | K7: 0.5 | M7: =((16*C7)+(4*D7*E7)) -> 57.330921 | O7: =(3.14*E7*E7*E7)*((I7-J7)+(K7*I7)) -> 90.077567 | Q7: =IF(M7>O7,"ERROR","OK") -> OK
A8: 6 | B8: 5.7 | C8: =SQRT(B8*B8+B8*B8) -> 8.0610173 | D8: 9.1 | E8: =H8/1000 -> 0.1922 | F8: 174.8 | G8: 209.6 | H8: =((G8-F8)/2)+F8 -> 192.2 | I8: =I$5 -> 13980 | J8: =O$3 -> 9323.2908 | K8: 0.5 | M8: =((16*C8)+(4*D8*E8)) -> 135.97236 | O8: =(3.14*E8*E8*E8)*((I8-J8)+(K8*I8)) -> 259.65281 | Q8: =IF(M8>O8,"ERROR","OK") -> OK
A9: 8 | B9: 10.4 | C9: =SQRT(B9*B9+B9*B9) -> 14.707821 | D9: 12.9 | E9: =H9/1000 -> 0.2398 | F9: 222.3 | G9: 257.3 | H9: =((G9-F9)/2)+F9 -> 239.8 | I9: =I$5 -> 13980 | J9: =O$3 -> 9323.2908 | K9: 0.5 | M9: =((16*C9)+(4*D9*E9)) -> 247.69882 | O9: =(3.14*E9*E9*E9)*((I9-J9)+(K9*I9)) -> 504.29007 | Q9: =IF(M9>O9,"ERROR","OK") -> OK | AB9: 16ME + 4FEG (LHS) | AE9: 3.14 G3[(PR-PD)+FMPR] (RHS)
A10: 10 | B10: 16.8 | C10: =SQRT(B10*B10+B10*B10) -> 23.758788 | D10: 16.9 | E10: =H10/1000 -> 0.2938 | F10: 276.4 | G10: 311.2 | H10: =((G10-F10)/2)+F10 -> 293.8 | I10: =I$5 -> 13980 | J10: =O$3 -> 9323.2908 | K10: 0.5 | M10: =((16*C10)+(4*D10*E10)) -> 400.00149 | O10: =(3.14*E10*E10*E10)*((I10-J10)+(K10*I10)) -> 927.44519 | Q10: =IF(M10>O10,"ERROR","OK") -> OK
A11: 12 | B11: 25 | C11: =SQRT(B11*B11+B11*B11) -> 35.355339 | D11: 21.1 | E11: =H11/1000 -> 0.3461 | F11: 323.9 | G11: 368.3 | H11: =((G11-F11)/2)+F11 -> 346.1 | I11: =I$5 -> 13980 | J11: =O$3 -> 9323.2908 | K11: 0.5 | M11: =((16*C11)+(4*D11*E11)) -> 594.89626 | O11: =(3.14*E11*E11*E11)*((I11-J11)+(K11*I11)) -> 1516.1343 | Q11: =IF(M11>O11,"ERROR","OK") -> OK | AB11: ME | AC11: External Moment
A12: 14 | B12: 35.3 | C12: =SQRT(B12*B12+B12*B12) -> 49.921739 | D12: 25.4 | E12: =H12/1000 -> 0.37785 | F12: 355.6 | G12: 400.1 | H12: =((G12-F12)/2)+F12 -> 377.85 | I12: =I$5 -> 13980 | J12: =O$3 -> 9323.2908 | K12: 0.3 | M12: =((16*C12)+(4*D12*E12)) -> 837.13738 | O12: =(3.14*E12*E12*E12)*((I12-J12)+(K12*I12)) -> 1499.2222 | Q12: =IF(M12>O12,"ERROR","OK") -> OK | AB12: FE | AC12: External Tensil axial Force
A13: 16 | B13: 47.8 | C13: =SQRT(B13*B13+B13*B13) -> 67.599408 | D13: 29.8 | E13: =H13/1000 -> 0.435 | F13: 412.8 | G13: 457.2 | H13: =((G13-F13)/2)+F13 -> 435 | I13: =I$5 -> 13980 | J13: =O$3 -> 9323.2908 | K13: 0.3 | M13: =((16*C13)+(4*D13*E13)) -> 1133.4425 | O13: =(3.14*E13*E13*E13)*((I13-J13)+(K13*I13)) -> 2287.5758 | Q13: =IF(M13>O13,"ERROR","OK") -> OK | AB13: G | AC13: Gasket reaction diameter
A14: 18 | B14: 62.8 | C14: =SQRT(B14*B14+B14*B14) -> 88.812612 | D14: 34.3 | E14: =H14/1000 -> 0.49215 | F14: 463.6 | G14: 520.7 | H14: =((G14-F14)/2)+F14 -> 492.15 | I14: =I$5 -> 13980 | J14: =O$3 -> 9323.2908 | K14: 0.3 | M14: =((16*C14)+(4*D14*E14)) -> 1488.5248 | O14: =(3.14*E14*E14*E14)*((I14-J14)+(K14*I14)) -> 3312.8379 | Q14: =IF(M14>O14,"ERROR","OK") -> OK | AB14: PR | AC14: Flange Pressure Rating at design temp
A15: 20 | B15: 80.4 | C15: =SQRT(B15*B15+B15*B15) -> 113.70277 | D15: 38.9 | E15: =H15/1000 -> 0.5461 | F15: 520.7 | G15: 571.5 | H15: =((G15-F15)/2)+F15 -> 546.1 | I15: =I$5 -> 13980 | J15: =O$3 -> 9323.2908 | K15: 0.3 | M15: =((16*C15)+(4*D15*E15)) -> 1904.2175 | O15: =(3.14*E15*E15*E15)*((I15-J15)+(K15*I15)) -> 4526.1011 | Q15: =IF(M15>O15,"ERROR","OK") -> OK | AB15: PD | AC15: Vessel MAWP corrected or design pressure
A16: 24 | B16: 124.3 | C16: =SQRT(B16*B16+B16*B16) -> 175.78675 | D16: 48.5 | E16: =H16/1000 -> 0.6541 | F16: 628.7 | G16: 679.5 | H16: =((G16-F16)/2)+F16 -> 654.1 | I16: =I$5 -> 13980 | J16: =O$3 -> 9323.2908 | K16: 0.3 | M16: =((16*C16)+(4*D16*E16)) -> 2939.4833 | O16: =(3.14*E16*E16*E16)*((I16-J16)+(K16*I16)) -> 7777.5026 | Q16: =IF(M16>O16,"ERROR","OK") -> OK | AB16: FM | AC16: Moment Factor (table UG-44-1)
A18: 26 | B18: 134.7 | C18: =SQRT(B18*B18+B18*B18) -> 190.49457 | D18: 52.5 | E18: =H18/1000 -> 0.7112 | F18: 685.8 | G18: 736.6 | H18: =((G18-F18)/2)+F18 -> 711.2 | I18: =I$5 -> 13980 | J18: =O$3 -> 9323.2908 | K18: 0.1 | M18: =((16*C18)+(4*D18*E18)) -> 3197.2651 | O18: =(3.14*E18*E18*E18)*((I18-J18)+(K18*I18)) -> 6839.0878 | Q18: =IF(M18>O18,"ERROR","OK") -> OK
A19: 28 | B19: 145 | C19: =SQRT(B19*B19+B19*B19) -> 205.06097 | D19: 56.6 | E19: =H19/1000 -> 0.762 | F19: 736.6 | G19: 787.4 | H19: =((G19-F19)/2)+F19 -> 762 | I19: =I$5 -> 13980 | J19: =O$3 -> 9323.2908 | K19: 0.1 | M19: =((16*C19)+(4*D19*E19)) -> 3453.4923 | O19: =(3.14*E19*E19*E19)*((I19-J19)+(K19*I19)) -> 8411.779 | Q19: =IF(M19>O19,"ERROR","OK") -> OK
A20: 30 | B20: 155.4 | C20: =SQRT(B20*B20+B20*B20) -> 219.76879 | D20: 60.6 | E20: =H20/1000 -> 0.8192 | F20: 793.8 | G20: 844.6 | H20: =((G20-F20)/2)+F20 -> 819.2 | I20: =I$5 -> 13980 | J20: =O$3 -> 9323.2908 | K20: 0.1 | M20: =((16*C20)+(4*D20*E20)) -> 3714.8747 | O20: =(3.14*E20*E20*E20)*((I20-J20)+(K20*I20)) -> 10451.84 | Q20: =IF(M20>O20,"ERROR","OK") -> OK
A21: 32 | B21: 165.7 | C21: =SQRT(B21*B21+B21*B21) -> 234.33519 | D21: 64.7 | E21: =H21/1000 -> 0.8763 | F21: 850.9 | G21: 901.7 | H21: =((G21-F21)/2)+F21 -> 876.3 | I21: =I$5 -> 13980 | J21: =O$3 -> 9323.2908 | K21: 0.1 | M21: =((16*C21)+(4*D21*E21)) -> 3976.1494 | O21: =(3.14*E21*E21*E21)*((I21-J21)+(K21*I21)) -> 12793.264 | Q21: =IF(M21>O21,"ERROR","OK") -> OK
A22: 34 | B22: 176.1 | C22: =SQRT(B22*B22+B22*B22) -> 249.04301 | D22: 68.7 | E22: =H22/1000 -> 0.9271 | F22: 901.7 | G22: 952.5 | H22: =((G22-F22)/2)+F22 -> 927.1 | I22: =I$5 -> 13980 | J22: =O$3 -> 9323.2908 | K22: 0.1 | M22: =((16*C22)+(4*D22*E22)) -> 4239.4552 | O22: =(3.14*E22*E22*E22)*((I22-J22)+(K22*I22)) -> 15149.653 | Q22: =IF(M22>O22,"ERROR","OK") -> OK
A23: 36 | B23: 186.5 | C23: =SQRT(B23*B23+B23*B23) -> 263.75083 | D23: 72.8 | E23: =H23/1000 -> 0.9843 | F23: 958.9 | G23: 1009.7 | H23: =((G23-F23)/2)+F23 -> 984.3 | I23: =I$5 -> 13980 | J23: =O$3 -> 9323.2908 | K23: 0.1 | M23: =((16*C23)+(4*D23*E23)) -> 4506.6414 | O23: =(3.14*E23*E23*E23)*((I23-J23)+(K23*I23)) -> 18130.317 | Q23: =IF(M23>O23,"ERROR","OK") -> OK
A24: 38 | B24: 196.8 | C24: =SQRT(B24*B24+B24*B24) -> 278.31723 | D24: 76.8 | E24: =H24/1000 -> 1.0605 | F24: 1035.1 | G24: 1085.9 | H24: =((G24-F24)/2)+F24 -> 1060.5 | I24: =I$5 -> 13980 | J24: =O$3 -> 9323.2908 | K24: 0.1 | M24: =((16*C24)+(4*D24*E24)) -> 4778.8613 | O24: =(3.14*E24*E24*E24)*((I24-J24)+(K24*I24)) -> 22675.4 | Q24: =IF(M24>O24,"ERROR","OK") -> OK
A25: 40 | B25: 207.2 | C25: =SQRT(B25*B25+B25*B25) -> 293.02505 | D25: 80.8 | E25: =H25/1000 -> 1.124 | F25: 1098.6 | G25: 1149.4 | H25: =((G25-F25)/2)+F25 -> 1124 | I25: =I$5 -> 13980 | J25: =O$3 -> 9323.2908 | K25: 0.1 | M25: =((16*C25)+(4*D25*E25)) -> 5051.6776 | O25: =(3.14*E25*E25*E25)*((I25-J25)+(K25*I25)) -> 26997.396 | Q25: =IF(M25>O25,"ERROR","OK") -> OK
A26: 48 | B26: 248.6 | C26: =SQRT(B26*B26+B26*B26) -> 351.57349 | D26: 97 | E26: =H26/1000 -> 1.3462 | F26: 1320.8 | G26: 1371.6 | H26: =((G26-F26)/2)+F26 -> 1346.2 | I26: =I$5 -> 13980 | J26: =O$3 -> 9323.2908 | K26: 0.1 | M26: =((16*C26)+(4*D26*E26)) -> 6147.5015 | O26: =(3.14*E26*E26*E26)*((I26-J26)+(K26*I26)) -> 46382.238 | Q26: =IF(M26>O26,"ERROR","OK") -> OK
M27: =((16*C27)+(4*D27*E27)) -> 0
